<?xml version="1.0" ?>
<robot name="panda_gripper" xmlns:xacro="http://www.ros.org/wiki/xacro">
  <link name="base">
  </link>
  
  <joint name="hand_joint" type="prismatic">
    <parent link="base"/>
    <child link="hand"/>
    <axis xyz="0 1 0"/>
    <limit effort="300" lower="-2" upper="2" velocity="20"/>
  </joint>
  
  <link name="hand">
    <visual>
      <origin rpy="0 0 0" xyz="0 -0.07 0"/>
      <geometry>
        <mesh filename="package://franka_description/meshes/visual/hand.obj"/>
      </geometry>
    </visual>
    <collision>
      <origin rpy="4.71239 0 0" xyz="0 -0.07 0"/>
      <geometry>
        <mesh filename="package://franka_description/meshes/collision/hand.obj"/>
      </geometry>
    </collision>
  </link>
  
  <link name="left_finger">
    <visual>
      <geometry>  
        <mesh filename="package://franka_description/meshes/visual/finger.obj"/>
      </geometry>
    </visual>
    
    <collision>
      <origin rpy="4.71239 0 0" xyz="0 0 0"/>
      <geometry>
        <mesh filename="package://franka_description/meshes/collision/finger.obj"/>
      </geometry>
    </collision>
    
  </link>
  
  <joint name="finger_joint_left" type="prismatic">
    <parent link="hand"/>
    <child link="left_finger"/>
    <origin rpy="0 0 0" xyz="0 0 -0.04"/>
    <axis xyz="0 0 1"/>
    <limit effort="70" lower="0.00" upper="0.04" velocity="0.1"/>
  </joint>
  
  
  <link name="right_finger">
    <visual>
      <geometry>
        <mesh filename="package://franka_description/meshes/visual/finger.obj"/>
      </geometry>
    </visual>
    
    <collision>
    <origin rpy="4.71239 0 0" xyz="0 0 0"/>
      <geometry>
        <mesh filename="package://franka_description/meshes/collision/finger.obj"/>
      </geometry>
    </collision>
  </link>
  
  <joint name="finger_joint_right" type="prismatic">
    <parent link="hand"/>
    <child link="right_finger"/>
    <origin rpy="0 3.14 0" xyz="0 0 0.04"/>
    <axis xyz="0 0 1"/>
    <limit effort="70" lower="0.0" upper="0.04" velocity="0.1"/>
    <!--<mimic joint="finger_joint_left"/>-->
  </joint>
</robot>
  
